Workbook

Sheet Risikoanalyse
A1: Nummer | B1: Name | C1: Beschreibung | D1: Relevanz | E1: Eintrittshäufigkeit | F1: Schadenshöhe | G1: Risikohöhe | H1: Risikobehandlung | I1: Zusätzliche Anforderung (Dropdownmenü entspricht Auswahl aus dem Kompendium pro Gefährdung) | J1: Begründung
A2: G 0.1 | B2: Feuer | C2: Feuer können schwere Schäden an Menschen, Gebäuden und deren Einrichtung verursachen. Neben direkten durch Feuer verursachten Schäden lassen sich Folgeschäden aufzeigen, die insbesondere für die Informationstechnik in ihrer Schadenswirkung ein katastrophales Ausmaß erreichen können. Löschwasserschäden treten beispielsweise nicht nur an der Brandstelle auf. Sie können auch in tiefer liegenden Gebäudeteilen entstehen. Bei der Verbrennung von PVC entstehen Chlorgase, die zusammen mit der Luftfeuchtigkeit und dem Löschwasser Salzsäure bilden. Werden die Salzsäuredämpfe über die Klimaanlage verteilt, können auf diese Weise Schäden an empfindlichen elektronischen Geräten entstehen, die in einem vom Brandort weit entfernten Teil des Gebäudes stehen. Aber auch "normaler" Brandrauch kann auf diesem Weg beschädigend auf die IT-Einrichtung einwirken. Ein Brand entsteht nicht nur durch den fahrlässigen Umgang mit Feuer (z. B. durch unbeaufsichtigte offene Flammen, Schweiß- und Lötarbeiten), sondern auch durch unsachgemäße Benutzung elektrischer Einrichtungen (z. B. unbeaufsichtigte Kaffeemaschine, Überlastung von Mehrfachsteckdosen). Technische Defekte an elektrischen Geräten können ebenfalls zu einem Brand führen. | D2: Direkt relevant | E2: 1 selten | F2: 2 begrenzt | G2: =IF(OR(F2="",E2=""),"",VLOOKUP(CONCATENATE(E2,"/",F2),'Zusätzliche Anforderungen'!$N$1295:$O$1310,2,FALSE)) -> gering | H2: Risikoreduktion | I2: INF.2.A28 Einsatz von höherwertigen Gefahrenmeldeanlagen
A3: G 0.2 | B3: Ungünstige klimatische Bedingungen | C3: Ungünstige klimatische Bedingungen wie Hitze, Frost oder hohe Luftfeuchtigkeit können zu Schäden verschiedenster Art führen, beispielsweise zu Fehlfunktionen in technischen Komponenten oder zur Beschädigung von Speichermedien. Häufige Schwankungen der klimatischen Bedingungen verstärken diesen Effekt. Ungünstige klimatische Bedingungen können auch dazu führen, dass Menschen nicht mehr arbeiten können oder sogar verletzt oder getötet werden. Jeder Mensch und jedes technische Gerät hat einen Temperaturbereich, innerhalb dessen seine normale Arbeitsweise bzw. ordnungsgemäße Funktion gewährleistet ist. Überschreitet die Umgebungstemperatur die Grenzen dieses Bereiches nach oben oder unten, kann es zu Arbeitsausfällen, Betriebsstörungen oder zu Geräteausfällen kommen. Zu Lüftungszwecken werden oft unerlaubt Fenster von Serverräumen geöffnet. In der Übergangszeit (Frühjahr, Herbst) kann das bei großen Temperaturschwankungen dazu führen, dass durch starke Abkühlung die zulässige Luftfeuchte überschritten wird. | G3: =IF(OR(F3="",E3=""),"",VLOOKUP(CONCATENATE(E3,"/",F3),'Zusätzliche Anforderungen'!$N$1295:$O$1310,2,FALSE))
A4: G 0.3 | B4: Wasser | C4: Durch Wasser kann die Integrität und Verfügbarkeit von Informationen beeinträchtigt werden, die auf analogen und digitalen Datenträgern gespeichert sind. Auch Informationen im Arbeitsspeicher von ITSystemen sind gefährdet. Der unkontrollierte Eintritt von Wasser in Gebäude oder Räume kann beispielsweise bedingt sein durch: • Störungen in der Wasser-Versorgung oder Abwasser-Entsorgung, • Defekte der Heizungsanlage, • Defekte an Klimaanlagen mit Wasseranschluss, • Defekte in Sprinkleranlagen, • Löschwasser bei der Brandbekämpfung und • Wassersabotage z. B. durch Öffnen der Wasserhähne und Verstopfen der Abflüsse. Unabhängig davon, auf welche Weise Wasser in Gebäude oder Räume gelangt, besteht die Gefahr, dass Versorgungseinrichtungen oder IT-Komponenten beschädigt oder außer Betrieb gesetzt werden (Kurzschluss, mechanische Beschädigung, Rost etc.). Besonders wenn zentrale Einrichtungen der Gebäudeversorgung (Hauptverteiler für Strom, Telefon, Daten) in Kellerräumen ohne selbsttätige Entwässerung untergebracht sind, kann eindringendes Wasser sehr hohe Schäden verursachen. Probleme können außerdem durch Frost entstehen. Beispielsweise können Rohre in frostgefährdeten Bereichen undicht werden, wenn darin Wasser bei anhaltendem Frost stillsteht. Auch eine vorhandene Wärmedämmung wird mit der Zeit vom Frost überwunden. | G4: =IF(OR(F4="",E4=""),"",VLOOKUP(CONCATENATE(E4,"/",F4),'Zusätzliche Anforderungen'!$N$1295:$O$1310,2,FALSE))
A5: G 0.4 | B5: Verschmutzung, Staub, Korrosion | C5: Viele IT-Geräte enthalten neben der Elektronik auch mechanisch arbeitende Komponenten, wie z. B. bei Fest- und Wechselplatten, DVD-Laufwerken, Druckern, Scannern etc., aber auch Lüftern von Prozessoren und Netzteilen. Mit steigenden Anforderungen an die Qualität und die Schnelligkeit müssen diese Geräte immer präziser arbeiten. Bereits geringfügige Verunreinigungen können zu einer Störung eines Gerätes führen. Staub und Verschmutzungen können beispielsweise durch folgende Tätigkeiten in größerem Maße entstehen: • Arbeiten an Wänden, Doppelböden oder anderen Gebäudeteilen, • Umrüstungsarbeiten an der Hardware bzw. • Entpackungsaktionen von Geräten (z. B. aufwirbelndes Styropor). Vorhandene Sicherheitsschaltungen in den Geräten führen meist zu einem rechtzeitigen Abschalten. Das hält zwar den direkten Schaden am Gerät, die Instandsetzungskosten und die Ausfallzeiten klein, führt aber dazu, dass das betroffene Gerät nicht verfügbar ist. Die Geräte und die Infrastruktur können außerdem durch Korrosion angegriffen werden. Dies kann sich nicht nur auf die IT, sondern sogar auf die Sicherheit von Gebäuden negativ auswirken. Durch Korrosion können auch indirekt weitere Gefährdungen entstehen. So kann beispielsweise Wasser aus korrodierten Stellen austreten (siehe G 0.3 Wasser). Insgesamt können Verschmutzung, Staub oder Korrosion somit zu Ausfällen oder Beschädigungen von ITKomponenten und Versorgungseinrichtungen führen. Als Folge kann die ordnungsgemäße Informationsverarbeitung beeinträchtigt werden. | G5: =IF(OR(F5="",E5=""),"",VLOOKUP(CONCATENATE(E5,"/",F5),'Zusätzliche Anforderungen'!$N$1295:$O$1310,2,FALSE))
A6: G 0.5 | B6: Naturkatastrophen | C6: Unter Naturkatastrophen werden natürliche Veränderungen verstanden, die verheerende Auswirkungen auf Menschen und Infrastrukturen haben. Ursachen für eine Naturkatastrophe können seismische, klimatische oder vulkanische Phänomene sein, wie beispielsweise Erdbeben, Hochwasser, Erdrutsche, Tsunamis, Lawinen und Vulkanausbrüche. Beispiele für extreme meteorologische Phänomene sind Unwetter, Orkane oder Zyklone. Je nach Standort der Institution ist diese den Risiken durch die verschiedenen Arten von Naturkatastrophen unterschiedlich stark ausgesetzt. Beispiele: • Für Rechenzentren in Hochwasser-gefährdeten Gebieten besteht oft in besonderem Maße die Gefahr, dass unkontrolliert Wasser in das Gebäude eindringt (Überschwemmungen oder Anstieg des Grundwasserspiegels). • Die Häufigkeit von Erdbeben und somit auch das damit verbundene Risiko hängen stark von der geografischen Lage ab. Unabhängig von der Art der Naturkatastrophe besteht auch in nicht unmittelbar betroffenen Gebieten die Gefahr, dass Versorgungseinrichtungen, Kommunikationsverbindungen oder IT-Komponenten beschädigt oder außer Betrieb gesetzt werden. Besonders der Ausfall zentraler Einrichtungen der Gebäudeversorgung (Hauptverteiler für Strom, Telefon, Daten) kann sehr hohe Schäden nach sich ziehen. Betriebs- und ServicePersonal kann aufgrund von großflächig eingerichteten Sperrbereichen der Zutritt zur Infrastruktur verwehrt werden. | G6: =IF(OR(F6="",E6=""),"",VLOOKUP(CONCATENATE(E6,"/",F6),'Zusätzliche Anforderungen'!$N$1295:$O$1310,2,FALSE))
A7: G 0.6 | B7: Katastrophen im Umfeld | C7: Eine Behörde bzw. ein Unternehmen kann Schaden nehmen, wenn sich im Umfeld ein schwerer Unglücksfall ereignet, zum Beispiel ein Brand, eine Explosion, die Freisetzung giftiger Substanzen oder das Austreten gefährlicher Strahlung. Gefahr besteht dabei nicht nur durch das Ereignis selbst, sondern auch durch die häufig daraus resultierenden Aktivitäten, beispielsweise Sperrungen oder Rettungsmaßnahmen. Die Liegenschaften einer Institution können verschiedenen Gefährdungen aus dem Umfeld ausgesetzt sein, unter anderem durch Verkehr (Straßen, Schiene, Luft, Wasser), Nachbarbetriebe oder Wohngebiete. Vorbeugungs- oder Rettungsmaßnahmen können die Liegenschaften dabei direkt betreffen. Solche Maßnahmen können auch dazu führen, dass Mitarbeiter ihre Arbeitsplätze nicht erreichen können oder Personal evakuiert werden muss. Durch die Komplexität der Haustechnik und der IT-Einrichtungen kann es aber auch zu indirekten Problemen kommen. | G7: =IF(OR(F7="",E7=""),"",VLOOKUP(CONCATENATE(E7,"/",F7),'Zusätzliche Anforderungen'!$N$1295:$O$1310,2,FALSE))
A8: G 0.7 | B8: Großereignisse im Umfeld | C8: Großveranstaltungen aller Art können zu Behinderungen des ordnungsgemäßen Betriebs einer Behörde bzw. eines Unternehmens führen. Hierzu gehören unter anderem Straßenfeste, Konzerte, Sportveranstaltungen, Arbeitskämpfe oder Demonstrationen. Ausschreitungen im Zusammenhang mit solchen Veranstaltungen können zusätzliche Auswirkungen, wie die Einschüchterung von Mitarbeitern bis hin zur Gewaltanwendung gegen das Personal oder das Gebäude, nach sich ziehen. | G8: =IF(OR(F8="",E8=""),"",VLOOKUP(CONCATENATE(E8,"/",F8),'Zusätzliche Anforderungen'!$N$1295:$O$1310,2,FALSE))
A9: G 0.8 | B9: Ausfall oder Störung der Stromversorgung | C9: Trotz hoher Versorgungssicherheit kommt es immer wieder zu Unterbrechungen der Stromversorgung seitens der Verteilungsnetzbetreiber (VNB) bzw. Energieversorgungsunternehmen (EVU). Die größte Zahl dieser Störungen ist mit Zeiten unter einer Sekunde so kurz, dass der Mensch sie nicht bemerkt. Aber schon Unterbrechungen von mehr als 10 ms sind geeignet, den IT-Betrieb zu stören. Neben Störungen im Versorgungsnetz können jedoch auch Abschaltungen bei nicht angekündigten Arbeiten oder Kabelbeschädigungen bei Tiefbauarbeiten dazu führen, dass die Stromversorgung ausfällt. Von der Stromversorgung sind nicht nur die offensichtlichen, direkten Stromverbraucher (PC, Beleuchtung usw.) abhängig. Viele Infrastruktur-Einrichtungen sind heute vom Strom abhängig, z.B. Aufzüge, Klimatechnik, Gefahrenmeldeanlagen, Sicherheitsschleusen, automatische Türschließanlagen und Sprinkleranlagen. Selbst die Wasserversorgung in Hochhäusern ist wegen der zur Druck-Erzeugung in den oberen Etagen erforderlichen Pumpen stromabhängig. Bei längeren Stromausfällen kann der Ausfall der Infrastruktur-Einrichtungen dazu führen, dass keinerlei Tätigkeiten mehr in den betroffenen Räumlichkeiten durchgeführt werden können. Neben Ausfällen können auch andere Störungen der Stromversorgung den Betrieb beeinträchtigen. Überspannung kann beispielsweise zu Fehlfunktionen oder sogar zu Beschädigungen von elektrischen Geräten führen. Zu beachten ist außerdem, dass durch Ausfälle oder Störungen der Stromversorgung in der Nachbarschaft unter Umständen auch die eigenen Geschäftsprozesse betroffen sein können, beispielsweise wenn Zufahrtswege blockiert werden. | G9: =IF(OR(F9="",E9=""),"",VLOOKUP(CONCATENATE(E9,"/",F9),'Zusätzliche Anforderungen'!$N$1295:$O$1310,2,FALSE))
A10: G 0.9 | B10: Ausfall oder Störung von Kommunikationsnetzen | C10: Für viele Geschäftsprozesse werden heutzutage zumindest zeitweise intakte Kommunikationsverbindungen benötigt, sei es über Telefon, Fax, E-Mail oder andere Dienste über Nah- oder Weitverkehrsnetze. Fallen einige oder mehrere dieser Kommunikationsverbindungen über einen längeren Zeitraum aus, kann dies beispielsweise dazu führen, dass • Geschäftsprozesse nicht mehr weiterbearbeitet werden können, weil benötigte Informationen nicht abgerufen werden können, • Kunden die Institution nicht mehr für Rückfragen erreichen können, • Aufträge nicht abgegeben oder beendet werden können. Werden auf IT-Systemen, die über Weitverkehrsnetze verbunden sind, zeitkritische Anwendungen betrieben, sind die durch einen Netzausfall möglichen Schäden und Folgeschäden entsprechend hoch, wenn keine Ausweichmöglichkeiten (z. B. Anbindung an ein zweites Kommunikationsnetz) vorhanden sind. Zu ähnlichen Problemen kann es kommen, wenn die benötigten Kommunikationsnetze gestört sind, ohne jedoch vollständig auszufallen. Kommunikationsverbindungen können beispielsweise eine erhöhte Fehlerrate oder andere Qualitätsmängel aufweisen. Falsche Betriebsparameter können ebenfalls zu Beeinträchtigungen führen. | G10: =IF(OR(F10="",E10=""),"",VLOOKUP(CONCATENATE(E10,"/",F10),'Zusätzliche Anforderungen'!$N$1295:$O$1310,2,FALSE))
A11: G 0.10 | B11: Ausfall oder Störung von Versorgungsnetzen | C11: Es gibt in einem Gebäude eine Vielzahl von Netzen, die der grundlegenden Ver- und Entsorgung und somit als Basis für alle Geschäftsprozesse einer Institution einschließlich der IT dienen. Beispiele für solche Versorgungsnetze sind: • Strom, • Telefon, • Kühlung, • Heizung bzw. Lüftung, • Wasser und Abwasser, • Löschwasserspeisungen, • Gas, • Melde- und Steueranlagen (z. B. für Einbruch, Brand, Hausleittechnik) und • Sprechanlagen. Der Ausfall oder die Störung eines Versorgungsnetzes kann unter anderem dazu führen, dass Menschen nicht mehr im Gebäude arbeiten können oder dass der IT-Betrieb und somit die Informationsverarbeitung beeinträchtigt wird. Die Netze sind in unterschiedlich starker Weise voneinander abhängig, so dass sich Betriebsstörungen in jedem einzelnen Netz auch auf andere auswirken können. | G11: =IF(OR(F11="",E11=""),"",VLOOKUP(CONCATENATE(E11,"/",F11),'Zusätzliche Anforderungen'!$N$1295:$O$1310,2,FALSE))
A12: G 0.11 | B12: Ausfall oder Störung von Dienstleistern | C12: Kaum eine Institution arbeitet heute noch ohne Dienstleister wie Zulieferer oder Outsourcing-Anbieter. Wenn Organisationseinheiten von Dienstleistern abhängig sind, kann durch Ausfälle externer Dienstleistungen die Aufgabenbewältigung beeinträchtigt werden. Der teilweise oder vollständige Ausfall eines Outsourcing-Dienstleisters oder eines Zulieferers kann sich erheblich auf die betriebliche Kontinuität auswirken, insbesondere bei kritischen Geschäftsprozessen. Es gibt verschiedene Ursachen für solche Ausfälle, beispielsweise Insolvenz, einseitige Kündigung des Vertrags durch den Dienstleister oder Zulieferer, betriebliche Probleme beispielsweise durch Naturgewalten oder Personalausfall. Probleme können auch entstehen, wenn die vom Dienstleister erbrachten Leistungen nicht den Qualitätsanforderungen des Auftraggebers entsprechen. Zu beachten ist außerdem, dass Dienstleister ebenfalls häufig auf Unterauftragnehmer zurückgreifen, um ihre Leistungen gegenüber dem Auftraggeber zu erbringen. Störungen, Qualitätsmängel und Ausfälle seitens der Unterauftragnehmer können dadurch indirekt zu Beeinträchtigungen beim Auftraggeber führen. Auch durch Ausfälle von IT-Systemen beim Dienstleister oder der Kommunikationsanbindungen zu diesem können Geschäftsprozesse beim Auftraggeber beeinträchtigt werden. Eine gegebenenfalls notwendige Rückholung ausgelagerter Prozesse kann stark erschwert sein, beispielsweise weil die ausgelagerten Verfahren nicht hinreichend dokumentiert sind oder weil der bisherige Dienstleister die Rückholung nicht unterstützt. | G12: =IF(OR(F12="",E12=""),"",VLOOKUP(CONCATENATE(E12,"/",F12),'Zusätzliche Anforderungen'!$N$1295:$O$1310,2,FALSE))
A13: G 0.12 | B13: Elektromagnetische Störstrahlung | C13: Informationstechnik setzt sich heute zu einem großen Teil aus elektronischen Komponenten zusammen. Zwar wird zunehmend auch optische Übertragungstechnik eingesetzt, dennoch enthalten beispielsweise Computer, Netzkoppelelemente und Speichersysteme in der Regel sehr viele elektronische Bauteile. Durch elektromagnetische Störstrahlung, die auf solche Bauteile einwirkt, können elektronische Geräte in ihrer Funktion beeinträchtigt oder sogar beschädigt werden. Als Folge kann es unter anderem zu Ausfällen, Störungen, falschen Verarbeitungsergebnissen oder Kommunikationsfehlern kommen. Auch drahtlose Kommunikation kann durch elektromagnetische Störstrahlung beeinträchtigt werden. Hierzu reicht unter Umständen eine ausreichend starke Störung der verwendeten Frequenzbänder. Weiterhin können Informationen, die auf bestimmten Arten von Datenträgern gespeichert sind, durch elektromagnetische Störstrahlung gelöscht oder verfälscht werden. Dies betrifft insbesondere magnetisierbare Datenträger (Festplatten, Magnetbänder etc.) und Halbleiter-Speicher. Auch eine Beschädigung solcher Datenträger durch elektromagnetische Störstrahlung ist möglich. Es gibt viele unterschiedliche Quellen elektromagnetischer Felder oder Strahlung, zum Beispiel Funknetze wie WLAN, Bluetooth, GSM, UMTS etc., Dauermagnete und kosmische Strahlung. Außerdem strahlt jedes elektrische Gerät mehr oder weniger starke elektromagnetische Wellen ab, die sich unter anderem durch die Luft und entlang metallischer Leiter (z. B. Kabel, Klimakanäle, Heizungsrohre etc.) ausbreiten können. In Deutschland enthält das Gesetz über die elektromagnetische Verträglichkeit von Betriebsmitteln (EMVG) Regelungen zu diesem Thema. | G13: =IF(OR(F13="",E13=""),"",VLOOKUP(CONCATENATE(E13,"/",F13),'Zusätzliche Anforderungen'!$N$1295:$O$1310,2,FALSE))
A14: G 0.13 | B14: Abfangen kompromittierender Strahlung | C14: Elektrische Geräte strahlen elektromagnetische Wellen ab. Bei Geräten, die Informationen verarbeiten (z. B. Computer, Bildschirme, Netzkoppelelemente, Drucker), kann diese Strahlung auch die gerade verarbeiteten Informationen mit sich führen. Derartige informationstragende Abstrahlung wird bloßstellende oder kompromittierende Abstrahlung genannt. Ein Angreifer, der sich beispielsweise in einem Nachbarhaus oder in einem in der Nähe abgestellten Fahrzeug befindet, kann versuchen, diese Abstrahlung zu empfangen und daraus die verarbeiteten Informationen zu rekonstruieren. Die Vertraulichkeit der Informationen ist damit in Frage gestellt. Eine mögliche Zielsetzung eines solchen Angriffes ist Industriespionage. Die Grenzwerte des Gesetzes über die elektromagnetische Verträglichkeit von Betriebsmitteln (EMVG) reichen im Allgemeinen nicht aus, um das Abfangen der bloßstellenden Abstrahlung zu verhindern. Falls dieses Risiko nicht akzeptiert werden kann, müssen deshalb in aller Regel zusätzliche Schutzmaßnahmen getroffen werden. Bloßstellende Abstrahlung ist nicht auf elektromagnetische Wellen beschränkt. Auch aus Schallwellen, zum Beispiel bei Druckern oder Tastaturen, können unter Umständen nützliche Informationen gewonnen werden. Zu beachten ist außerdem, dass bloßstellende Abstrahlung in bestimmten Fällen auch durch äußere Manipulation von Geräten verursacht oder verstärkt werden kann. Wird zum Beispiel ein Gerät mit elektromagnetischen Wellen bestrahlt, kann es passieren, dass die reflektierten Wellen vertrauliche Informationen mit sich führen. | G14: =IF(OR(F14="",E14=""),"",VLOOKUP(CONCATENATE(E14,"/",F14),'Zusätzliche Anforderungen'!$N$1295:$O$1310,2,FALSE))
... A46: G 0.45 | B46: Datenverlust | C46: Ein Datenverlust ist ein Ereignis, das dazu führt, dass ein Datenbestand nicht mehr wie erforderlich genutzt werden kann (Verlust der Verfügbarkeit). Eine häufige Form des Datenverlustes ist, dass Daten unbeabsichtigt oder unerlaubt gelöscht werden, zum Beispiel durch Fehlbedienung, Fehlfunktionen, Stromausfälle, Verschmutzung oder Schadsoftware. Ein Datenverlust kann jedoch auch durch Beschädigung, Verlust oder Diebstahl von Geräten oder Datenträgern entstehen. Dieses Risiko ist bei mobilen Endgeräten und mobilen Datenträgern häufig besonders hoch. Weiterhin ist zu beachten, dass viele mobile IT-Systeme nicht immer online sind. Die auf diesen Systemen gespeicherten Daten befinden sich daher nicht immer auf dem aktuellsten Stand. Wenn Datenbestände zwischen mobilen IT-Systemen und stationären IT-Systemen synchronisiert werden, kann es durch Unachtsamkeit oder Fehlfunktion zu Datenverlusten kommen. | G46: =IF(OR(F46="",E46=""),"",VLOOKUP(CONCATENATE(E46,"/",F46),'Zusätzliche Anforderungen'!$N$1295:$O$1310,2,FALSE))
A47: G 0.46 | B47: Integritätsverlust schützenswerter Informationen | C47: Die Integrität von Informationen kann durch verschiedene Ursachen beeinträchtigt werden, z. B. durch Manipulationen, Fehlverhalten von Personen, Fehlbedienung von Anwendungen, Fehlfunktionen von Software oder Übermittlungsfehler. • Durch die Alterung von Datenträgern kann es zu Informationsverlusten kommen. • Übertragungsfehler: Bei der Datenübertragung kann es zu Übertragungsfehlern kommen. • Schadprogramme: Durch Schadprogramme können ganze Datenbestände verändert oder zerstört werden. • Fehleingaben: Durch Fehleingaben kann es zu so nicht gewünschten Transaktionen kommen, die häufig lange Zeit nicht bemerkt werden. • Angreifer können versuchen, Daten für ihre Zwecke zu manipulieren, z. B. um Zugriff auf weitere ITSysteme oder Datenbestände zu erlangen. • Durch Manipulation der Index-Datenbank können elektronische Archive veranlasst werden, gefälschte Dokumente zu archivieren oder wiederzugeben. Wenn Informationen nicht mehr integer sind, kann es zu einer Vielzahl von Problemen kommen: • Informationen können im einfachsten Fall nicht mehr gelesen, also weiterverarbeitet werden. • Daten können versehentlich oder vorsätzlich so verfälscht werden, dass dadurch falsche Informationen weitergegeben werden. Hierdurch können beispielsweise Überweisungen in falscher Höhe oder an den falschen Empfänger ausgelöst werden, die Absenderangaben von E-Mails könnten manipuliert werden oder vieles mehr. • Wenn verschlüsselte oder komprimierte Datensätze ihre Integrität verlieren (hier reicht die Änderung eines Bits), können sie unter Umständen nicht mehr entschlüsselt bzw. entpackt werden. • Dasselbe gilt auch für kryptographische Schlüssel, auch hier reicht die Änderung eines Bits, damit die Schlüssel unbrauchbar werden. Dies führt dann ebenfalls dazu, dass Daten nicht mehr entschlüsselt oder auf ihre Authentizität überprüft werden können. • Dokumente, die in elektronischen Archiven gespeichert sind, verlieren an Beweiskraft, wenn ihre Integrität nicht nachgewiesen werden kann. | D47: Indirekt relevant | G47: =IF(OR(F47="",E47=""),"",VLOOKUP(CONCATENATE(E47,"/",F47),'Zusätzliche Anforderungen'!$N$1295:$O$1310,2,FALSE))
A48: G 0.47 | B48: Schädliche Seiteneffekte IT-gestützter Angriffe | C48: IT-gestützte Angriffe können Auswirkungen haben, die • von den Tätern nicht beabsichtigt sind oder • nicht die unmittelbar angegriffenen Zielobjekte betreffen oder • unbeteiligte Dritte schädigen. Ursächlich hierfür sind die hohe Komplexität und Vernetzung moderner Informationstechnik sowie die Tatsache, dass die Abhängigkeiten der angegriffenen Zielobjekte und der zugehörigen Prozesse in der Regel nicht offenkundig sind. Dadurch kann es unter anderem dazu kommen, dass der tatsächliche Schutzbedarf von Zielobjekten falsch eingeschätzt wird oder dass die Verantwortlichen für die Zielobjekte kein Eigeninteresse an der Behebung von Mängeln dieser Zielobjekte haben. | E48: 1 selten | F48: 2 begrenzt | G48: =IF(OR(F48="",E48=""),"",VLOOKUP(CONCATENATE(E48,"/",F48),'Zusätzliche Anforderungen'!$N$1295:$O$1310,2,FALSE)) -> gering

Sheet Risikobewertung

Sheet Zusätzliche Anforderungen
A1: Zusätzliche Anforderungen | B1: relevante Gefährdungen
A2: INF.12.A17 Redundanzen für die IT-Verkabelung | B2: G 0.1
A3: INF.5.A18 Lage des Raumes für technische Infrastruktur | B3: G 0.1
A4: INF.2.A28 Einsatz von höherwertigen Gefahrenmeldeanlagen | B4: G 0.1
A5: APP.3.1.A20 Einsatz von Web Application Firewalls | B5: G 0.1
A6: INF.8.A6 Umgang mit dienstlichen Unterlagen bei erhöhtem Schutzbedarf am häuslichen Arbeitsplatz | B6: G 0.1
A7: IND.1.A24 Alternative und unabhängige Kommunikationsmöglichkeiten SOLLTEN aufgebaut und betrieben werden. | B7: G 0.1
A8: INF.1.A22 Sichere Türen und Fenster | B8: G 0.1
A9: INF.1.A34 Gefahrenmeldeanlage | B9: G 0.1
A10: INF.5.A25 Erhöhter Schutz vor Schädigung durch Brand und Rauchgase | B10: G 0.1
A11: INF.6.A9 Gefahrenmeldeanlage | B11: G 0.1
A12: INF.11.A16 Brandlöschanlage | B12: G 0.1
... A1188: SYS.2.1.A34 Kapselung von sicherheitskritischen Anwendungen und Betriebssystemkomponenten | B1188: G 0.45
A1189: IND.2.1.A18 Kommunikation im Störfall | B1189: G 0.45 | N1189: Gefährdung | O1189: Eintrittsw | P1189: Schaden
A1190: SYS.2.1.A32 Einsatz zusätzlicher Maßnahmen zum Schutz vor Exploits | B1190: G 0.45 | N1190: G 0.1 | O1190: =IFERROR(VALUE(LEFT(Risikoanalyse!E2,1))-0.5,-1) -> 0.5 | P1190: =IFERROR(VALUE(LEFT(Risikoanalyse!F2,1))-0.5,-1) -> 1.5
A1191: SYS.2.1.A33 Application Whitelisting | B1191: G 0.45 | N1191: G 0.2 | O1191: =IFERROR(VALUE(LEFT(Risikoanalyse!E3,1))-0.5,-1) -> -1 | P1191: =IFERROR(VALUE(LEFT(Risikoanalyse!F3,1))-0.5,-1) -> -1
A1192: NET.3.2.A25 Erweiterter Integritätsschutz für die Konfigurationsdateien | B1192: G 0.45 | N1192: G 0.3 | O1192: =IFERROR(VALUE(LEFT(Risikoanalyse!E4,1))-0.5,-1) -> -1 | P1192: =IFERROR(VALUE(LEFT(Risikoanalyse!F4,1))-0.5,-1) -> -1
A1193: NET.3.1.A28 Einsatz von zertifizierten Produkten | B1193: G 0.45 | N1193: G 0.4 | O1193: =IFERROR(VALUE(LEFT(Risikoanalyse!E5,1))-0.5,-1) -> -1 | P1193: =IFERROR(VALUE(LEFT(Risikoanalyse!F5,1))-0.5,-1) -> -1
A1194: NET.1.2.A38 Festlegung von Notbetriebsformen für die Netzmanagement-Infrastruktur | B1194: G 0.45 | N1194: G 0.5 | O1194: =IFERROR(VALUE(LEFT(Risikoanalyse!E6,1))-0.5,-1) -> -1 | P1194: =IFERROR(VALUE(LEFT(Risikoanalyse!F6,1))-0.5,-1) -> -1
A1195: SYS.1.7.A38 Einsatz des VTAM Session Management Exit unter z/OS | B1195: G 0.45 | N1195: G 0.6 | O1195: =IFERROR(VALUE(LEFT(Risikoanalyse!E7,1))-0.5,-1) -> -1 | P1195: =IFERROR(VALUE(LEFT(Risikoanalyse!F7,1))-0.5,-1) -> -1
A1196: APP.1.1.A15 Einsatz von Verschlüsselung und Digitalen Signaturen | B1196: G 0.46 | N1196: G 0.7 | O1196: =IFERROR(VALUE(LEFT(Risikoanalyse!E8,1))-0.5,-1) -> -1 | P1196: =IFERROR(VALUE(LEFT(Risikoanalyse!F8,1))-0.5,-1) -> -1
A1197: DER.2.2.A15 Durchführung von Übungen zur Beweissicherung | B1197: G 0.46 | N1197: G 0.8 | O1197: =IFERROR(VALUE(LEFT(Risikoanalyse!E9,1))-0.5,-1) -> -1 | P1197: =IFERROR(VALUE(LEFT(Risikoanalyse!F9,1))-0.5,-1) -> -1
A1198: DER.2.3.A9 Hardwaretausch betroffener IT-Systeme | B1198: G 0.46 | N1198: G 0.9 | O1198: =IFERROR(VALUE(LEFT(Risikoanalyse!E10,1))-0.5,-1) -> -1 | P1198: =IFERROR(VALUE(LEFT(Risikoanalyse!F10,1))-0.5,-1) -> -1
A1199: DER.2.2.A14 Festlegung von Standardverfahren für die Beweissicherung | B1199: G 0.46 | N1199: G 0.10 | O1199: =IFERROR(VALUE(LEFT(Risikoanalyse!E11,1))-0.5,-1) -> -1 | P1199: =IFERROR(VALUE(LEFT(Risikoanalyse!F11,1))-0.5,-1) -> -1
A1200: DER.2.1.A20 Einrichtung einer internen Meldestelle für Sicherheitsvorfälle | B1200: G 0.46 | N1200: G 0.11 | O1200: =IFERROR(VALUE(LEFT(Risikoanalyse!E12,1))-0.5,-1) -> -1 | P1200: =IFERROR(VALUE(LEFT(Risikoanalyse!F12,1))-0.5,-1) -> -1
A1201: DER.2.1.A21 Einrichtung eines Expertenteams für die Behandlung von Sicherheitsvorfällen | B1201: G 0.46 | N1201: G 0.12 | O1201: =IFERROR(VALUE(LEFT(Risikoanalyse!E13,1))-0.5,-1) -> -1 | P1201: =IFERROR(VALUE(LEFT(Risikoanalyse!F13,1))-0.5,-1) -> -1
... A1236: OPS.1.1.5.A12 Verschlüsselung der Protokollierungsdaten | B1236: G 0.46 | N1236: G 0.47 | O1236: =IFERROR(VALUE(LEFT(Risikoanalyse!E48,1))-0.5,-1) -> 0.5 | P1236: =IFERROR(VALUE(LEFT(Risikoanalyse!F48,1))-0.5,-1) -> 1.5
A1237: SYS.1.3.A14 Verhinderung des Ausspähens von System- und Benutzerinformationen | B1237: G 0.46
A1238: SYS.1.2.2.A14 Herunterfahren verschlüsselter Server und virtueller Maschinen | B1238: G 0.46
A1239: SYS.1.7.A35 Einsatz von RACF-Exits | B1239: G 0.46
A1240: SYS.2.3.A18 Zusätzlicher Schutz des Kernels | B1240: G 0.46
A1241: SYS.2.2.2.A20 Sicherheit beim Fernzugriff über RDP | B1241: G 0.46
A1242: SYS.1.7.A36 Interne Kommunikation von Betriebssystemen | B1242: G 0.46
A1243: SYS.1.8.A23 Einsatz von Verschlüsselung für Speicherlösungen | B1243: G 0.46
A1244: SYS.1.7.A38 Einsatz des VTAM Session Management Exit unter z/OS | B1244: G 0.46
A1245: SYS.1.1.A34 Festplattenverschlüsselung | B1245: G 0.46
A1246: SYS.1.8.A24 Sicherstellung der Integrität der SAN-Fabric | B1246: G 0.46
A1247: SYS.2.2.2.A21 Einsatz von File und Registry Virtualization | B1247: G 0.46
A1248: APP.4.3.A24 Datenverschlüsselung in der Datenbank | B1248: G 0.46
... A1269: INF.1.A35 Perimeterschutz | B1269: G 0.7
...
